<?xml version="1.0" encoding="utf-8"?>

<robot
  name="tricycle_mobile_robot">

  <!-- ROS_CONTROL_PLUGIN -->
  <gazebo>
    <plugin name="gazebo_ros_control" filename="libgazebo_ros_control.so">
      <robotNamespace>/tricycle_mobile_robot</robotNamespace>
      <!--<odometryFrame>odom</odometryFrame>
      <legacyModeNS>false</legacyModeNS>
      <robotBaseFrame>base_footprint</robotBaseFrame>-->
    </plugin>
  </gazebo>

   <link name="base_footprint">
    <inertial>
      <mass value="0.0001" />
      <origin xyz="0 0 0" />
      <inertia ixx="0.0001" ixy="0.0" ixz="0.0"
          iyy="0.0001" iyz="0.0" 
          izz="0.0001" />
    </inertial>
    <visual>
        <origin xyz="0 0 0" rpy="0 0 0" />
        <geometry>
            <box size="0.001 0.001 0.001" />
        </geometry>
    </visual>
  </link>

  <link
    name="base_link">
    <inertial>
      <origin
        xyz="-1.0227 3.8638E-08 -0.12641"
        rpy="0 0 0" />
      <mass
        value="10.0" />
      <inertia
        ixx="306.12"
        ixy="-3.0018E-05"
        ixz="1.2421"
        iyy="241.78"
        iyz="3.9312E-06"
        izz="538.54" />
    </inertial>
    <visual>
      <origin
        xyz="0 0 0"
        rpy="0 0 0" />
      <geometry>
        <mesh
          filename="package://tricycle_mobile_robot/meshes/base_link.STL" />
      </geometry>
      <material
        name="">
        <color
          rgba="1 1 0 1" />
      </material>
    </visual>
    <collision>
      <origin
        xyz="0 0 0"
        rpy="0 0 0" />
      <geometry>
        <mesh
          filename="package://tricycle_mobile_robot/meshes/base_link.STL" />
      </geometry>
    </collision>
  </link>

  <gazebo reference="base_link">
      <material>Gazebo/Yellow</material>
  </gazebo>

  <joint name="base_footprint_joint" type="fixed">
    <origin xyz="0 0 0.574" rpy="0 0 0" />
    <parent link="base_footprint"/>
    <child link="base_link"/>
  </joint>

  <link
    name="wheel_br_link">
    <inertial>
      <origin
        xyz="2.2204E-16 1.1102E-16 -0.125"
        rpy="0 0 0" />
      <mass
        value="0.2" />
      <inertia
        ixx="1.3844"
        ixy="1.2889E-37"
        ixz="2.9387E-36"
        iyy="1.3844"
        iyz="-2.1533E-33"
        izz="2.608" />
    </inertial>
    <visual>
      <origin
        xyz="0 0 0"
        rpy="0 0 0" />
      <geometry>
        <mesh
          filename="package://tricycle_mobile_robot/meshes/wheel_br_link.STL" />
      </geometry>
      <material
        name="">
        <color
          rgba="0 0 0 1" />
      </material>
    </visual>
    <collision>
      <origin
        xyz="0 0 0"
        rpy="0 0 0" />
      <geometry>
        <mesh
          filename="package://tricycle_mobile_robot/meshes/wheel_br_link.STL" />
      </geometry>
    </collision>
  </link>

  <gazebo reference="wheel_br_link">
      <material>Gazebo/Black</material>
  </gazebo>

  <joint
    name="wheel_br_joint"
    type="continuous">
    <origin
      xyz="0 0.75 -0.245"
      rpy="1.5708 0 0" />
    <parent
      link="base_link" />
    <child
      link="wheel_br_link" />
    <axis
      xyz="0 0 1" />
    <limit
      effort="100"
      velocity="100" />
  </joint>
  <link
    name="wheel_bl_link">
    <inertial>
      <origin
        xyz="0 0 -0.125"
        rpy="0 0 0" />
      <mass
        value="0.2" />
      <inertia
        ixx="1.3844"
        ixy="1.2889E-37"
        ixz="-6.5614E-35"
        iyy="1.3844"
        iyz="-2.1533E-33"
        izz="2.608" />
    </inertial>
    <visual>
      <origin
        xyz="0 0 0"
        rpy="0 0 0" />
      <geometry>
        <mesh
          filename="package://tricycle_mobile_robot/meshes/wheel_bl_link.STL" />
      </geometry>
      <material
        name="">
        <color
          rgba="0 0 0 1" />
      </material>
    </visual>
    <collision>
      <origin
        xyz="0 0 0"
        rpy="0 0 0" />
      <geometry>
        <mesh
          filename="package://tricycle_mobile_robot/meshes/wheel_bl_link.STL" />
      </geometry>
    </collision>
  </link>

  <gazebo reference="wheel_bl_link">
      <material>Gazebo/Black</material>
  </gazebo>

  <joint
    name="wheel_bl_joint"
    type="continuous">
    <origin
      xyz="0 -1 -0.245"
      rpy="1.5708 0 0" />
    <parent
      link="base_link" />
    <child
      link="wheel_bl_link" />
    <axis
      xyz="0 0 1" />
    <limit
      effort="100"
      velocity="100" />
  </joint>
  <link
    name="steer_link">
    <inertial>
      <origin
        xyz="0 0 0"
        rpy="0 0 0" />
      <mass
        value="0.1" />
      <inertia
        ixx="0"
        ixy="0"
        ixz="0"
        iyy="0"
        iyz="0"
        izz="0" />
    </inertial>
    <visual>
      <origin
        xyz="0 0 0"
        rpy="0 0 0" />
      <geometry>
        <mesh
          filename="package://tricycle_mobile_robot/meshes/steer_link.STL" />
      </geometry>
      <material
        name="">
        <color
          rgba="1 1 1 1" />
      </material>
    </visual>
    <collision>
      <origin
        xyz="0 0 0"
        rpy="0 0 0" />
      <geometry>
        <mesh
          filename="package://tricycle_mobile_robot/meshes/steer_link.STL" />
      </geometry>
    </collision>
  </link>

  <gazebo reference="steer_link">
      <material>Gazebo/Yellow</material>
  </gazebo>

  <joint
    name="steer_joint"
    type="revolute">
    <origin
      xyz="-1.6 0 0"
      rpy="0 0 0" />
    <parent
      link="base_link" />
    <child
      link="steer_link" />
    <axis
      xyz="0 0 -1" />
    <limit
      lower="-0.7854"
      upper="0.7854"
      effort="1000"
      velocity="1000" />
  </joint>
  <link
    name="front_wheel_link">
    <inertial>
      <origin
        xyz="0 -1.1102E-16 0.075"
        rpy="0 0 0" />
      <mass
        value="0.1" />
      <inertia
        ixx="0.079728"
        ixy="6.074E-39"
        ixz="2.1215E-34"
        iyy="0.079728"
        iyz="-2.3318E-34"
        izz="0.11929" />
    </inertial>
    <visual>
      <origin
        xyz="0 0 0"
        rpy="0 0 0" />
      <geometry>
        <mesh
          filename="package://tricycle_mobile_robot/meshes/front_wheel_link.STL" />
      </geometry>
      <material
        name="">
        <color
          rgba="0 0 0 1" />
      </material>
    </visual>
    <collision>
      <origin
        xyz="0 0 0"
        rpy="0 0 0" />
      <geometry>
        <mesh
          filename="package://tricycle_mobile_robot/meshes/front_wheel_link.STL" />
      </geometry>
    </collision>
  </link>

  <gazebo reference="front_wheel_link">
      <material>Gazebo/Black</material>
  </gazebo>

  <joint
    name="front_wheel_joint"
    type="continuous">
    <origin
      xyz="0 0.075 -0.425"
      rpy="1.5708 0 0" />
    <parent
      link="steer_link" />
    <child
      link="front_wheel_link" />
    <axis
      xyz="0 0 -1" />
    <limit
      effort="10000"
      velocity="1000" />
  </joint>

  <transmission name="steer_trans">
    <type>transmission_interface/SimpleTransmission</type>
    <joint name="steer_joint">
      <hardwareInterface>EffortJointInterface</hardwareInterface>
    </joint>
    <actuator name="steer_motor">
      <hardwareInterface>EffortJointInterface</hardwareInterface>
      <mechanicalReduction>1</mechanicalReduction>
    </actuator>
  </transmission>

  <transmission name="wheel_trans">
    <type>transmission_interface/SimpleTransmission</type>
    <joint name="front_wheel_joint">
      <hardwareInterface>EffortJointInterface</hardwareInterface>
    </joint>
    <actuator name="wheel_motor">
      <hardwareInterface>EffortJointInterface</hardwareInterface>
      <mechanicalReduction>1</mechanicalReduction>
    </actuator>
  </transmission>

  <transmission name="wheel_bl_trans">
    <type>transmission_interface/SimpleTransmission</type>
    <joint name="wheel_bl_joint">
      <hardwareInterface>EffortJointInterface</hardwareInterface>
    </joint>
    <actuator name="wheel_bl_motor">
      <hardwareInterface>EffortJointInterface</hardwareInterface>
      <mechanicalReduction>1</mechanicalReduction>
    </actuator>
  </transmission>

  <transmission name="wheel_br_trans">
    <type>transmission_interface/SimpleTransmission</type>
    <joint name="wheel_br_joint">
      <hardwareInterface>EffortJointInterface</hardwareInterface>
    </joint>
    <actuator name="wheel_br_motor">
      <hardwareInterface>EffortJointInterface</hardwareInterface>
      <mechanicalReduction>1</mechanicalReduction>
    </actuator>
  </transmission>

</robot>
